Traceback (most recent call last):
  File "conkas.py", line 137, in <module>
    main()
  File "conkas.py", line 88, in main
    contracts = compile_files([filename])
  File "/usr/local/lib/python3.8/dist-packages/solcx/main.py", line 118, in compile_files
    stdoutdata, stderrdata, command, proc = solc_wrapper(**compiler_kwargs)
  File "/usr/local/lib/python3.8/dist-packages/solcx/utils/string.py", line 78, in inner
    return force_obj_to_text(fn(*args, **kwargs))
  File "/usr/local/lib/python3.8/dist-packages/solcx/wrapper.py", line 187, in solc_wrapper
    raise SolcError(
solcx.exceptions.SolcError: An error occurred during execution
        > command: `/root/.solcx/solc-v0.8.0 --combined-json abi,asm,ast,bin,bin-runtime,devdoc,opcodes,userdoc /data/Devoleum.sol`
        > return code: `1`
        > stderr:

        > stdout:
        Error: Source "@openzeppelin/contracts/access/Ownable.sol" not found: File outside of allowed directories.
 --> /data/Devoleum.sol:4:1:
  |
4 | import "@openzeppelin/contracts/access/Ownable.sol";
  | ^^^^^^^^^^^^^^^^^^^^^^^^^^^^^^^^^^^^^^^^^^^^^^^^^^^^

Error: Source "@openzeppelin/contracts/utils/math/SafeMath.sol" not found: File outside of allowed directories.
 --> /data/Devoleum.sol:5:1:
  |
5 | import "@openzeppelin/contracts/utils/math/SafeMath.sol";
  | ^^^^^^^^^^^^^^^^^^^^^^^^^^^^^^^^^^^^^^^^^^^^^^^^^^^^^^^^^